Workbook

Sheet Yearly Pricing
A1: Year | B1: Utility $/mo | C1: Solar $/mo | D1: Savings $/mo | E1: Savings $/Year | F1: % Saved
A2: 1 | B2: 134.3895 | C2: 124.0106 | D2: 10.3789 | E2: 124.5469 | F2: 0.083693777
A3: 2 | B3: 140.8939 | C3: 128.3689 | D3: 12.525 | E3: 274.8468 | F3: 0.097570215
A4: 3 | B4: 147.7132 | C4: 132.8807 | D4: 14.8325 | E4: 452.8363 | F4: 0.11162234
A5: 4 | B5: 154.8625 | C5: 137.5514 | D5: 17.3112 | E5: 660.5702 | F5: 0.12585233
A6: 5 | B6: 162.3579 | C6: 142.3864 | D6: 19.9715 | E6: 900.2276 | F6: 0.14026237
A7: 6 | B7: 170.216 | C7: 147.3917 | D7: 22.8243 | E7: 1174.1191 | F7: 0.1548547
A8: 7 | B8: 178.4544 | C8: 152.5732 | D8: 25.8812 | E8: 1484.6939 | F8: 0.16963156
A9: 8 | B9: 187.0916 | C9: 157.9372 | D9: 29.1544 | E9: 1834.5473 | F9: 0.18459523
A10: 9 | B10: 196.1469 | C10: 163.49 | D10: 32.6568 | E10: 2226.429 | F10: 0.19974802
A11: 10 | B11: 205.6404 | C11: 169.2385 | D11: 36.4019 | E11: 2663.2516 | F11: 0.21509225
A12: 11 | B12: 215.5934 | C12: 175.1894 | D12: 40.404 | E12: 3148.0994 | F12: 0.23063028
A13: 12 | B13: 226.0281 | C13: 181.3499 | D13: 44.6782 | E13: 3684.2375 | F13: 0.2463645
... A26: 25 | B26: 417.8434 | C26: 284.2667 | D26: 133.5767 | E26: 17204.845 | F26: 0.46989907

Sheet Dashboard
A1: Energy Savings Dashboard
A3: Two options: keep riding utility rate hikes, or lock in predictability.
A4: Option A: Utility (variable) | C4: Option B: Solar (predictable) | E4: Monthly Advantage | G4: Total Advantage
A5: =Model!D4 -> 1612.6737 | C5: =Model!E4 -> 1488.1267 | E5: =Model!F4/12 -> 10.378912 | G5: =Model!J28 -> 17204.845
A7: Decision shortcut: if Monthly Advantage is positive, you are already ahead. Savings can only compound unless utilities stop raising rates.
A8: Monthly Cost Over Time
F9: Average Yearly Savings, First 10 Years
D10: Quick Compare | F10: =TEXT(SUM(Model!F2:F28)/24,"$#,##0")&" per Year" -> $717 per Year | J10: Year | K10: Utility $/mo | L10: Solar $/mo | M10: Savings $/mo | N10: Savings $/Year | O10: % Saved | U10: =IFERROR(MATCH(TRUE,$O$11:$O$41,0),"") | V10: Gauge
D11: Current Utility Rate | E11: Effective Sunrun Rate | J11: 1 | K11: =IF(1>Inputs!$E$12,"",Model!D4/12) -> 134.38947 | L11: =Model!E4/12 -> 124.01056 | M11: =Model!F4/12 -> 10.378912 | N11: =Model!J4 -> 124.54695 | O11: =Model!P4 -> 0.083693777 | U11: =IF(U10="","",INDEX($J$11:$J$41,U10)) | V11: =U14 -> 57
D12: =TEXT($C$27,"$0.000")&" per kWh" -> $0.383 per kWh | E12: =TEXT(Dashboard!C5/Inputs!K6,"$0.000")&" per kWh" -> $0.332 per kWh | J12: 2 | K12: =IF(1>Inputs!$E$12,"",Model!D5/12) -> 140.89392 | L12: =Model!E5/12 -> 128.36894 | M12: =Model!F5/12 -> 12.524985 | N12: =Model!J5 -> 274.84677 | O12: =Model!P5 -> 0.097570215 | R12: Year | S12: Utility $/mo | T12: Solar $/mo | V12: =MAX(0,100-U14) -> 43
F13: =IF($U$11="","N/A",$U$11&" years") -> N/A | J13: 3 | K13: =IF(1>Inputs!$E$12,"",Model!D6/12) -> 147.71319 | L13: =Model!E6/12 -> 132.88073 | M13: =Model!F6/12 -> 14.832458 | N13: =Model!J6 -> 452.83627 | O13: =Model!P6 -> 0.11162234 | R13: 1 | T13: =IF(1>Inputs!$E$12,"",INDEX(Model!$E:$E,3+1)/12) -> 124.01056 | U13: =MAX(0,MIN(100,ROUND(60 + 500*Inputs!$E$8 - 400*Inputs!$E$11 + 0.8*(Inputs!$E$12-10),0))) -> 82 | V13: 100
J14: 4 | K14: =IF(1>Inputs!$E$12,"",Model!D7/12) -> 154.86251 | L14: =Model!E7/12 -> 137.55135 | M14: =Model!F7/12 -> 17.311157 | N14: =Model!J7 -> 660.57016 | O14: =Model!P7 -> 0.12585233 | R14: 5 | S14: =IF(5>Inputs!$E$12,"",INDEX(Model!$D:$D,3+5)/12) -> 162.35785 | U14: =MAX(0,MIN(100,ROUND(35+MIN(30,MAX(0,$E$5)/50)+MIN(20,MAX(0,$G$5)/2500)+MIN(15,MAX(0,Inputs!$E$13)*15)+IF($U$11="",0,MAX(0,25-3*$U$11)),0))) -> 57
F15: Simple rule | J15: 5 | K15: =IF(1>Inputs!$E$12,"",Model!D8/12) -> 162.35785 | L15: =Model!E8/12 -> 142.3864 | M15: =Model!F8/12 -> 19.971454 | N15: =Model!J8 -> 900.2276 | O15: =Model!P8 -> 0.14026237 | R15: 10 | S15: =IF(10>Inputs!$E$12,"",INDEX(Model!$D:$D,3+10)/12) -> 205.64036
J16: 6 | K16: =IF(1>Inputs!$E$12,"",Model!D9/12) -> 170.21597 | L16: =Model!E9/12 -> 147.39168 | M16: =Model!F9/12 -> 22.824294 | N16: =Model!J9 -> 1174.1191 | O16: =Model!P9 -> 0.1548547
J17: 7 | K17: =IF(1>Inputs!$E$12,"",Model!D10/12) -> 178.45443 | L17: =Model!E10/12 -> 152.5732 | M17: =Model!F10/12 -> 25.88123 | N17: =Model!J10 -> 1484.6939 | O17: =Model!P10 -> 0.16963156
F18: Today utility rate | J18: 8 | K18: =IF(1>Inputs!$E$12,"",Model!D11/12) -> 187.09162 | L18: =Model!E11/12 -> 157.93717 | M18: =Model!F11/12 -> 29.154449 | N18: =Model!J11 -> 1834.5473 | O18: =Model!P11 -> 0.18459523
A19: Today vs 5 Years From Now | F19: Risk Snapshot | J19: 9 | K19: =IF(1>Inputs!$E$12,"",Model!D12/12) -> 196.14686 | L19: =Model!E12/12 -> 163.49004 | M19: =Model!F12/12 -> 32.656812 | N19: =Model!J12 -> 2226.429 | O19: =Model!P12 -> 0.19974802
A20: Yearly Utility (Today) | C20: =A5 -> 1612.6737 | F20: ✅ Predictable monthly cost | J20: 10 | K20: =IF(1>Inputs!$E$12,"",Model!D13/12) -> 205.64036 | L20: =Model!E13/12 -> 169.23848 | M20: =Model!F13/12 -> 36.401885 | N20: =Model!J13 -> 2663.2516 | O20: =Model!P13 -> 0.21509225
A21: Yearly Solar (Today) | C21: =C5 -> 1488.1267 | F21: ✅ Hedge against rate hikes | J21: 11 | K21: =IF(1>Inputs!$E$12,"",Model!D14/12) -> 215.59336 | L21: =Model!E14/12 -> 175.18938 | M21: =Model!F14/12 -> 40.403976 | N21: =Model!J14 -> 3148.0994 | O21: =Model!P14 -> 0.23063028
A22: Utility(Pick Year | C22: =Model!D8/12 -> 162.35785 | F22: ✅ Better budget planning | J22: 12 | K22: =IF(1>Inputs!$E$12,"",Model!D15/12) -> 226.02808 | L22: =Model!E15/12 -> 181.3499 | M22: =Model!F15/12 -> 44.678177 | N22: =Model!J15 -> 3684.2375 | O22: =Model!P15 -> 0.2463645
A23: Solar (Year 5) | C23: =L15 -> 142.3864 | F23: =IF(INDEX($N$11:$N$41,25)>=0,"✅ WINNER: Solar saves "&TEXT(INDEX($N$11:$N$41,25),"$#,##0")&" by Year 25","⚠️ ALERT: Utility wins by "&TEXT(ABS(INDEX($N$11:$N$41,25)),"$#,##0")&" at Year 25") -> ✅ WINNER: Solar saves $15,602 by Year 25 | K23: =IF(1>Inputs!$E$12,"",Model!D16/12) -> 236.96783 | L23: =Model!E16/12 -> 187.72743 | M23: =Model!F16/12 -> 49.240401 | N23: =Model!J16 -> 4275.1223 | O23: =Model!P16 -> 0.26229731
A24: Cumulative Savings (Total Kept) | J24: 13 | K24: =IF(1>Inputs!$E$12,"",Model!D16/12) -> 236.96783 | L24: =Model!E16/12 -> 187.72743 | M24: =Model!F16/12 -> 49.240401 | N24: =Model!J16 -> 4275.1223 | O24: =Model!P16 -> 0.26229731
A25: Monthly Savings (Year 5) | C25: =Model!F8/12 -> 19.971454 | F25: Offset Breakdown | J25: 14 | K25: =IF(1>Inputs!$E$12,"",Model!D17/12) -> 248.43708 | L25: =Model!E17/12 -> 194.32965 | M25: =Model!F17/12 -> 54.10743 | N25: =Model!J17 -> 4924.4115 | O25: =Model!P17 -> 0.27843117
F26: =TEXT(Inputs!$E$13,"0%")&" offset" -> 99% offset | J26: 15 | K26: =IF(1>Inputs!$E$12,"",Model!D18/12) -> 260.46143 | L26: =Model!E18/12 -> 201.16448 | M26: =Model!F18/12 -> 59.296957 | N26: =Model!J18 -> 5635.9749 | O26: =Model!P18 -> 0.29476853
A27: Current effective $/kWh: | C27: =IFERROR(Inputs!$H$7/Inputs!$H$6,"") -> 0.38325359 | J27: 16 | K27: =IF(1>Inputs!$E$12,"",Model!D19/12) -> 273.06777 | L27: =Model!E19/12 -> 208.24013 | M27: =Model!F19/12 -> 64.827632 | N27: =Model!J19 -> 6413.9065 | O27: =Model!P19 -> 0.3113119
J28: 17 | K28: =IF(1>Inputs!$E$12,"",Model!D20/12) -> 286.28425 | L28: =Model!E20/12 -> 215.56513 | M28: =Model!F20/12 -> 70.719116 | N28: =Model!J20 -> 7262.5359 | O28: =Model!P20 -> 0.3280638
A29: Decision Confidence | J29: 18 | K29: =IF(1>Inputs!$E$12,"",Model!D21/12) -> 300.1404 | L29: =Model!E21/12 -> 223.14827 | M29: =Model!F21/12 -> 76.992132 | N29: =Model!J21 -> 8186.4415 | O29: =Model!P21 -> 0.34502679
A30: Monthly impact calculation (kWh and $ value at today's rate) | J30: 19 | K30: =IF(1>Inputs!$E$12,"",Model!D22/12) -> 314.6672 | L30: =Model!E22/12 -> 230.99868 | M30: =Model!F22/12 -> 83.668519 | N30: =Model!J22 -> 9190.4637 | O30: =Model!P22 -> 0.36220345
A31: =TEXT(U14,"0")&"/100" -> 57/100 | J31: 20 | K31: =IF(1>Inputs!$E$12,"",Model!D23/12) -> 329.89709 | L31: =Model!E23/12 -> 239.1258 | M31: =Model!F23/12 -> 90.771292 | N31: =Model!J23 -> 10279.719 | O31: =Model!P23 -> 0.3795964
J32: 21 | K32: =IF(1>Inputs!$E$12,"",Model!D24/12) -> 345.86411 | L32: =Model!E24/12 -> 247.53941 | M32: =Model!F24/12 -> 98.324702 | N32: =Model!J24 -> 11459.616 | O32: =Model!P24 -> 0.39720828
A33: If rates rise, solar looks even better. If rates stay flat, you still buy certainty. | J33: 22 | K33: =IF(1>Inputs!$E$12,"",Model!D25/12) -> 362.60393 | L33: =Model!E25/12 -> 256.24963 | M33: =Model!F25/12 -> 106.3543 | N33: =Model!J25 -> 12735.867 | O33: =Model!P25 -> 0.41504176
J34: 23 | K34: =IF(1>Inputs!$E$12,"",Model!D26/12) -> 380.15396 | L34: =Model!E26/12 -> 265.26696 | M34: =Model!F26/12 -> 114.887 | N34: =Model!J26 -> 14114.511 | O34: =Model!P26 -> 0.43309956
J35: 24 | K35: =IF(1>Inputs!$E$12,"",Model!D27/12) -> 398.55342 | L35: =Model!E27/12 -> 274.60224 | M35: =Model!F27/12 -> 123.95117 | N35: =Model!J27 -> 15601.925 | O35: =Model!P27 -> 0.45138441
J36: 25 | K36: =IF(1>Inputs!$E$12,"",Model!D28/12) -> 417.8434 | L36: =Model!E28/12 -> 284.26673 | M36: =Model!F28/12 -> 133.57667 | N36: =Model!J28 -> 17204.845 | O36: =Model!P28 -> 0.46989907
K37: =IF(26>Inputs!$E$12,"",Model!D29/12) | L37: =IF(26>Inputs!$E$12,"",Model!E29/12) | M37: =IF(26>Inputs!$E$12,"",Model!F29/12)
F38: Break-even | G38: Savings @ Year 10 | H38: Savings @ Year 25 | K38: =IF(27>Inputs!$E$12,"",Model!D30/12) | L38: =IF(27>Inputs!$E$12,"",Model!E30/12) | M38: =IF(27>Inputs!$E$12,"",Model!F30/12) | AB38: Year | AC38: UtilityAnnual | AD38: ResidualAfterOffset | AE38: S1_AnnSav | AF38: S1_CumSav | AG38: S2_AnnSav | AH38: S2_CumSav | AI38: S3_AnnSav | AJ38: S3_CumSav | AK38: S1_Pos | AL38: S2_Pos | AM38: S3_Pos
F39: =IFERROR(INDEX($AB$39:$AB$63, MATCH(TRUE,$AK$39:$AK$63,0)),"25+") -> 1 | G39: =INDEX($AF$39:$AF$63,10) -> 2679.3784 | H39: =INDEX($AF$39:$AF$63,25) -> 17220.972 | K39: =IF(28>Inputs!$E$12,"",Model!D31/12) | L39: =IF(28>Inputs!$E$12,"",Model!E31/12) | M39: =IF(28>Inputs!$E$12,"",Model!F31/12) | AB39: 1 | AC39: =INDEX(Model!$D:$D,3+AB39) -> 1612.6737 | AD39: =MAX(0,AC39*((Inputs!$E$13)-1)) -> 0 | AE39: =AC39-(AD39+($B$65*12-Inputs!$E$14)*POWER(1+$C$65,AB39-1)) -> 140.67368 | AF39: =AE39 -> 140.67368 | AG39: =AC39-(AD39+($B$66*12-Inputs!$E$14)*POWER(1+$C$66,AB39-1)) -> -1203.3263 | AH39: =AG39 -> -1203.3263 | AI39: =AC39-(AD39+($B$67*12-Inputs!$E$14)*POWER(1+$C$67,AB39-1)) -> 47.073684 | AJ39: =AI39 -> 47.073684 | AK39: =AF39>=0 -> TRUE | AL39: =AH39>=0 -> FALSE | AM39: =AJ39>=0 -> TRUE
F40: =IFERROR(INDEX($AB$39:$AB$63, MATCH(TRUE,$AL$39:$AL$63,0)),"25+") -> 25+ | G40: =INDEX($AH$39:$AH$63,10) -> -13087.614 | H40: =INDEX($AH$39:$AH$63,25) -> -35127.635 | K40: =IF(29>Inputs!$E$12,"",Model!D32/12) | L40: =IF(29>Inputs!$E$12,"",Model!E32/12) | M40: =IF(29>Inputs!$E$12,"",Model!F32/12) | AB40: =AB39+1 -> 2 | AC40: =INDEX(Model!$D:$D,3+AB40) -> 1690.7271 | AD40: =MAX(0,AC40*(1-MIN(Inputs!$E$13,1))) -> 16.907271 | AE40: =AC40-(AD40+($B$65*12-Inputs!$E$14)*POWER(1+$C$65,AB40-1)) -> 150.29982 | AF40: =AF39+AE40 -> 290.9735 | AG40: =AC40-(AD40+($B$66*12-Inputs!$E$14)*POWER(1+$C$66,AB40-1)) -> -1240.7402 | AH40: =AH39+AG40 -> -2444.0665 | AI40: =AC40-(AD40+($B$67*12-Inputs!$E$14)*POWER(1+$C$67,AB40-1)) -> 61.40838 | AJ40: =AJ39+AI40 -> 108.48206 | AK40: =AF40>=0 -> TRUE | AL40: =AH40>=0 -> FALSE | AM40: =AJ40>=0 -> TRUE
F41: =IFERROR(INDEX($AB$39:$AB$63, MATCH(TRUE,$AM$39:$AM$63,0)),"25+") -> 1 | G41: =INDEX($AJ$39:$AJ$63,10) -> 2008.4031 | H41: =INDEX($AJ$39:$AJ$63,25) -> 17549.421 | K41: =IF(30>Inputs!$E$12,"",Model!D33/12) | L41: =IF(30>Inputs!$E$12,"",Model!E33/12) | M41: =IF(30>Inputs!$E$12,"",Model!F33/12) | AB41: =AB40+1 -> 3 | AC41: =INDEX(Model!$D:$D,3+AB41) -> 1772.5583 | AD41: =MAX(0,AC41*(1-MIN(Inputs!$E$13,1))) -> 17.725583 | AE41: =AC41-(AD41+($B$65*12-Inputs!$E$14)*POWER(1+$C$65,AB41-1)) -> 177.9895 | AF41: =AF40+AE41 -> 468.963 | AG41: =AC41-(AD41+($B$66*12-Inputs!$E$14)*POWER(1+$C$66,AB41-1)) -> -1261.7369 | AH41: =AH40+AG41 -> -3705.8034 | AI41: =AC41-(AD41+($B$67*12-Inputs!$E$14)*POWER(1+$C$67,AB41-1)) -> 94.210157 | AJ41: =AJ40+AI41 -> 202.69222 | AK41: =AF41>=0 -> TRUE | AL41: =AH41>=0 -> FALSE | AM41: =AJ41>=0 -> TRUE
AB42: =AB41+1 -> 4 | AC42: =INDEX(Model!$D:$D,3+AB42) -> 1858.3501 | AD42: =MAX(0,AC42*(1-MIN(Inputs!$E$13,1))) -> 18.583501 | AE42: =AC42-(AD42+($B$65*12-Inputs!$E$14)*POWER(1+$C$65,AB42-1)) -> 207.73389 | AF42: =AF41+AE42 -> 676.69689 | AG42: =AC42-(AD42+($B$66*12-Inputs!$E$14)*POWER(1+$C$66,AB42-1)) -> -1282.3829 | AH42: =AH41+AG42 -> -4988.1863 | AI42: =AC42-(AD42+($B$67*12-Inputs!$E$14)*POWER(1+$C$67,AB42-1)) -> 129.49145 | AJ42: =AJ41+AI42 -> 332.18367 | AK42: =AF42>=0 -> TRUE | AL42: =AH42>=0 -> FALSE | AM42: =AJ42>=0 -> TRUE
...

Sheet Inputs
A1: Utility + Solar Model
A2: Orange cells are inputs. | B2: Column D overrides presets when filled.
G3: INPUT YOUR BILL BELOW
A4: Input | B4: Preset | C4: Preset Value | D4: Customer Override | E4: Effective Value
A5: Customer Name | C5: DO NOT ADJUST VALUES | G5: Current Utility Bill
A6: Current Utility ($/kWh) | B6: Customer | C6: =IF(B6="","",IFERROR(VLOOKUP(B6,Presets!$A$5:$B$12,2,FALSE),"")) -> 0.35933014 | E6: =IF(D6<>"",D6,IF(B6="Customer",C6,C6)) -> 0.35933014 | G6: Current Month Kwh | H6: 418 | J6: Yearly Kwh | K6: =SUM(H14:H25) -> 4488
A7: Avg. Monthly Usage (kWh) | C7: =K10 -> 374 | E7: =IF(D7<>"",D7,IF(B7="Customer",C7,C7)) -> 374 | G7: Amount Due | H7: 160.2 | J7: Effective $/Kwh | K7: =(H7-10)/H6 -> 0.35933014
A8: Utility Annual Rate Increase (%/yr) | B8: National 5yr | C8: =IF(B8="","",IFERROR(VLOOKUP(B8,Presets!$A$16:$B$22,2,FALSE),"")) -> 0.0484 | E8: =IF(D8<>"",D8,IF(B8="Customer","",C8)) -> 0.0484 | J8: Est Monthly Avg Bill | K8: =K9/12 -> 144.38947
A9: CPI Inflation (%/yr) | B9: National 10yr avg | C9: =IF(B9="","",IFERROR(VLOOKUP(B9,Presets!$A$28:$B$33,2,FALSE),"")) -> 0.0286 | E9: =IF(D9<>"",D9,IF(B9="Customer","",C9)) -> 0.0286 | J9: Est Yearly Utility | K9: =SUM(I14:I25) -> 1732.6737
A10: Solar Monthly Payment ($/mo) | D10: 156 | E10: =IF(D10<>"",D10,IF(B10="Customer","",C10)) -> 156 | J10: Avg Monthly Kwh | K10: =SUM(H14:H25)/12 -> 374
A11: Solar Annual Escalator (%/yr) | B11: 0.035 | D11: 0.035 | E11: =IF(D11<>"",D11,IF(B11="Customer","",C11)) -> 0.035
A12: Term (years) | C12: 25 | D12: 25 | E12: =D12 -> 25
A13: Solar % Offset (of usage) | D13: 0.99 | E13: =D13 -> 0.99 | G13: Month | H13: Usage, Kwh | I13: Est. Monthly Bill
A14: Rebates ($/yr) | C14: 0 | D14: 400 | E14: =IF(D14<>"",D14,C14) -> 400 | G14: Jan | H14: 418 | I14: =H14*K7+10 -> 160.2
G15: Feb | H15: 346 | I15: =H15*K7+10 -> 134.32823
G16: Mar | H16: 340 | I16: =H16*K7+10 -> 132.17225
G17: Apr | H17: 322 | I17: =H17*K7+10 -> 125.70431
G18: May | H18: 363 | I18: =K7*H18+10 -> 140.43684
G19: Jun | H19: 317 | I19: =K7*H19+10 -> 123.90766
G20: Jul | H20: 384 | I20: =K7*H20+10 -> 147.98278
G21: Aug | H21: 516 | I21: =K7*H21+10 -> 195.41435
G22: Sep | H22: 466 | I22: =K7*H22+10 -> 177.44785
G23: Oct | H23: 388 | I23: =K7*H23+10 -> 149.4201
G24: Nov | H24: 306 | I24: =K7*H24+10 -> 119.95502
G25: Dec | H25: 322 | I25: =K7*H25+10 -> 125.70431
C30: 2 batt | D30: 1 batt | E30: 2 batt | G30: 1 batt
C31: 0.035 | D31: 0.035 | E31: 2.99 | G31: 2.99
B32: 0.32 | D32: 268
B33: 0.295 | D33: 251
B34: 0.28 | D34: 242 | G34: 247
B35: 0.27 | D35: 235 | G35: 240

Sheet Sheet3
B1: Name | D1: Ranney | E1: Furness
A2: Usage | D2: 912 | E2: 418
D3: 766 | E3: 346
D4: 606 | E4: 340
D5: 496 | E5: 322
D6: 535 | E6: 363
D7: 560 | E7: 317
D8: 716 | E8: 384
D9: 961 | E9: 516
D10: 629 | E10: 466
D11: 573 | E11: 388
D12: 587 | E12: 306
D13: 544 | E13: 322

Sheet Presets
A1: Presets (edit values here if you want to customize)
A3: Current Utility $/kWh presets
A4: Preset | B4: Value ($/kWh) | D4: Source
A5: Customer | B5: =Inputs!K7 -> 0.35933014 | D5: https://www.eia.gov/electricity/sales_revenue_price/
A6: New England (Residential avg) | B6: 0.2768 | C6: EIA Form EIA-861M (computed); 2024 aligns with EIA Table 5A (U.S. Energy Information Administration)
A7: Massachusetts (Residential avg) | B7: 0.2935 | C7: EIA Form EIA-861M (computed); 2024 aligns with EIA Table 5A (U.S. Energy Information Administration)
A8: National Grid MA (Mass Electric Co) | B8: 0.336 | C8: 2024 utility avg from EIA Table 6 (U.S. Energy Information Administration); history proxy = MA statewide* (U.S. Energy Information Administration)
A9: Eversource (NSTAR Electric Co) | B9: 0.2991 | C9: 2024 utility avg from EIA Table 6 (U.S. Energy Information Administration); history proxy = MA statewide* (U.S. Energy Information Administration)
A10: Unitil (Fitchburg Gas & Electric Light Co) | B10: 0.4008 | C10: 2024 utility avg from EIA Table 6 (U.S. Energy Information Administration); history proxy = MA statewide* (U.S. Energy Information Administration)
A11: Westborough, MA (served by National Grid basic service territory) | B11: 0.336 | C11: Westborough listed in National Grid basic service territory ; price as Mass Electric Co 2024 avg (U.S. Energy Information Administration); history proxy = MA statewide* (U.S. Energy Information Administration)
A12: Clinton, MA (served by National Grid basic service territory) | B12: 0.336 | C12: Clinton listed in National Grid basic service territory ; price as Mass Electric Co 2024 avg (U.S. Energy Information Administration); history proxy = MA statewide* (U.S. Energy Information Administration)
A14: Utility annual rate increase presets
A15: Preset | B15: Value (%/yr)
A16: Customer | B16: 0.1124 | C16: Last year, central MA average
A17: MA 5yr | B17: 0.0601 | C17: CAGR of MA residential price 2019→2024 | D17: EIA Form EIA-861M (computed)
A18: MA 10yr | B18: 0.0537 | C18: CAGR 2014→2024 | D18: EIA Form EIA-861M (computed)
A19: MA 25yr | B19: 0.0436 | C19: CAGR 1999→2024 | D19: EIA Form EIA-861M (computed)
A20: NE 5yr | B20: 0.0557 | C20: CAGR 2019→2024 | D20: EIA Form EIA-861M (computed)
A21: NE 10yr | B21: 0.045 | C21: CAGR 2014→2024 | D21: EIA Form EIA-861M (computed)
A22: National 5yr | B22: 0.0484 | C22: CAGR US residential 2019→2024 | D22: EIA Form EIA-861M (computed)
A26: CPI inflation presets
A27: Preset | B27: Value (%/yr)
A28: Customer | B28: 0.08 | D28: https://fred.stlouisfed.org/series/CPIAUCSL
A29: MA 5yr | B29: 0.036569422 | D29: Regional CPI series used (Boston area + Northeast) to estimate MA/NE CPI CAGRs
A30: NE 5yr | B30: 0.038873395
A31: National 5yr avg | B31: 0.0417 | C31: CPI level CAGR 2019→2024 | D31: Minneapolis Fed CPI table
A32: National 10yr avg | B32: 0.0286 | C32: CPI level CAGR 2014→2024 | D32: Minneapolis Fed CPI table
A34: Solar Annual Escalator
A35: Preset | B35: Value(%/yr)
A36: 0.035 | B36: 0.035
A37: 2.99%(Prime Qual) | B37: 0.0299 | C37: Prime Qualification only available based on system performance and early adoptio

Sheet Model
A1: Year-by-Year Model
A3: Year | B3: Utility Rate ($/kWh) | C3: Annual kWh | D3: Utility Cost ($) | E3: Cost w Solar ($) | F3: Savings Per Year ($) | G3: CPI | H3: Utility Cost(Inf. Adj.) | I3: Solar+Utility(Inf. Adj. | J3: Cumulative Savings | K3: Savings, Inf. Adj. | L3: Lifetime Savings, Inf. Adj. ($) | M3: solar/mo w/ rebate | N3: solar/mo before rebate | O3: Avg Utility/mo | P3: % Savings | Q3: % Savings BEFORE rebate
A4: 1 | B4: =IF($A4>Inputs!$E$12,"",Inputs!$E$6*(1+Inputs!$E$8)^($A4-1)) -> 0.35933014 | C4: =IF($A4>Inputs!$E$12,"",Inputs!$E$7*12) -> 4488 | D4: =B4*C4 -> 1612.6737 | E4: =(B4*C4*(1-Inputs!$E$13))+(Inputs!$E$10*12-Inputs!$E$14) -> 1488.1267 | F4: =D4-E4 -> 124.54695 | G4: =(Inputs!$E$9)^($A4-1)-100% -> 0 | H4: =D4/(G4+100%) -> 1612.6737 | I4: =E4/(G4+100%) -> 1488.1267 | J4: =D4-E4 -> 124.54695 | K4: =H4-I4 -> 124.54695 | L4: =K4 -> 124.54695 | M4: =E4/12 -> 124.01056 | N4: =(E4+800)/12 -> 190.67723 | O4: =D4/12 -> 134.38947 | P4: =D4/E4-1 -> 0.083693777 | Q4: =O4/N4-1 -> -0.29519914
A5: 2 | B5: =IF($A5>Inputs!$E$12,"",Inputs!$E$6*(1+Inputs!$E$8)^($A5-1)) -> 0.37672172 | C5: =IF($A5>Inputs!$E$12,"",Inputs!$E$7*12) -> 4488 | D5: =B5*C5 -> 1690.7271 | E5: =(B5*C5*(1-Inputs!$E$13))+(Inputs!$E$10*12-Inputs!$E$14)*((1+Inputs!$E$11)^($A4)) -> 1540.4273 | F5: =D5-E5 -> 150.29982 | G5: =(1+Inputs!$E$9)^($A5-1)-100% -> 0.0286 | H5: =D5/(G5+100%) -> 1643.7168 | I5: =E5/(G5+100%) -> 1497.596 | J5: =J4+F5 -> 274.84677 | K5: =H5-I5 -> 146.12077 | L5: =L4+K5 -> 270.66771 | M5: =E5/12 -> 128.36894 | N5: =(E5+800)/12 -> 195.03561 | O5: =D5/12 -> 140.89392 | P5: =D5/E5-1 -> 0.097570215 | Q5: =O5/N5-1 -> -0.27759896
A6: 3 | B6: =IF($A6>Inputs!$E$12,"",Inputs!$E$6*(1+Inputs!$E$8)^($A6-1)) -> 0.39495505 | C6: =IF($A6>Inputs!$E$12,"",Inputs!$E$7*12) -> 4488 | D6: =B6*C6 -> 1772.5583 | E6: =(B6*C6*(1-Inputs!$E$13))+(Inputs!$E$10*12-Inputs!$E$14)*((1+Inputs!$E$11)^($A5)) -> 1594.5688 | F6: =D6-E6 -> 177.9895 | G6: =(1+Inputs!$E$9)^($A6-1)-100% -> 0.05801796 | H6: =D6/(G6+100%) -> 1675.3575 | I6: =E6/(G6+100%) -> 1507.1283 | J6: =J5+F6 -> 452.83627 | K6: =H6-I6 -> 168.22918 | L6: =L5+K6 -> 438.8969 | M6: =E6/12 -> 132.88073 | N6: =(E6+800)/12 -> 199.5474 | O6: =D6/12 -> 147.71319 | P6: =D6/E6-1 -> 0.11162234 | Q6: =O6/N6-1 -> -0.25975888
A7: 4 | B7: =IF($A7>Inputs!$E$12,"",Inputs!$E$6*(1+Inputs!$E$8)^($A7-1)) -> 0.41407088 | C7: =IF($A7>Inputs!$E$12,"",Inputs!$E$7*12) -> 4488 | D7: =B7*C7 -> 1858.3501 | E7: =(B7*C7*(1-Inputs!$E$13))+(Inputs!$E$10*12-Inputs!$E$14)*((1+Inputs!$E$11)^($A6)) -> 1650.6162 | F7: =D7-E7 -> 207.73389 | G7: =(1+Inputs!$E$9)^($A7-1)-100% -> 0.088277274 | H7: =D7/(G7+100%) -> 1707.6072 | I7: =E7/(G7+100%) -> 1516.724 | J7: =J6+F7 -> 660.57016 | K7: =H7-I7 -> 190.88324 | L7: =L6+K7 -> 629.78014 | M7: =E7/12 -> 137.55135 | N7: =(E7+800)/12 -> 204.21802 | O7: =D7/12 -> 154.86251 | P7: =D7/E7-1 -> 0.12585233 | Q7: =O7/N7-1 -> -0.24168048
A8: 5 | B8: =IF($A8>Inputs!$E$12,"",Inputs!$E$6*(1+Inputs!$E$8)^($A8-1)) -> 0.43411191 | C8: =IF($A8>Inputs!$E$12,"",Inputs!$E$7*12) -> 4488 | D8: =B8*C8 -> 1948.2942 | E8: =(B8*C8*(1-Inputs!$E$13))+(Inputs!$E$10*12-Inputs!$E$14)*((1+Inputs!$E$11)^($A7)) -> 1708.6368 | F8: =D8-E8 -> 239.65745 | G8: =(1+Inputs!$E$9)^($A8-1)-100% -> 0.119402 | H8: =D8/(G8+100%) -> 1740.4777 | I8: =E8/(G8+100%) -> 1526.3835 | J8: =J7+F8 -> 900.2276 | K8: =H8-I8 -> 214.09417 | L8: =L7+K8 -> 843.87431 | M8: =E8/12 -> 142.3864 | N8: =(E8+800)/12 -> 209.05307 | O8: =D8/12 -> 162.35785 | P8: =D8/E8-1 -> 0.14026237 | Q8: =O8/N8-1 -> -0.22336536
A9: 6 | B9: =IF($A9>Inputs!$E$12,"",Inputs!$E$6*(1+Inputs!$E$8)^($A9-1)) -> 0.45512293 | C9: =IF($A9>Inputs!$E$12,"",Inputs!$E$7*12) -> 4488 | D9: =B9*C9 -> 2042.5917 | E9: =(B9*C9*(1-Inputs!$E$13))+(Inputs!$E$10*12-Inputs!$E$14)*((1+Inputs!$E$11)^($A8)) -> 1768.7002 | F9: =D9-E9 -> 273.89153 | G9: =(1+Inputs!$E$9)^($A9-1)-100% -> 0.1514169 | H9: =D9/(G9+100%) -> 1773.981 | I9: =E9/(G9+100%) -> 1536.1075 | J9: =J8+F9 -> 1174.1191 | K9: =H9-I9 -> 237.87347 | L9: =L8+K9 -> 1081.7478 | M9: =E9/12 -> 147.39168 | N9: =(E9+800)/12 -> 214.05835 | O9: =D9/12 -> 170.21597 | P9: =D9/E9-1 -> 0.1548547 | Q9: =O9/N9-1 -> -0.20481506
A10: 7 | B10: =IF($A10>Inputs!$E$12,"",Inputs!$E$6*(1+Inputs!$E$8)^($A10-1)) -> 0.47715087 | C10: =IF($A10>Inputs!$E$12,"",Inputs!$E$7*12) -> 4488 | D10: =B10*C10 -> 2141.4531 | E10: =(B10*C10*(1-Inputs!$E$13))+(Inputs!$E$10*12-Inputs!$E$14)*((1+Inputs!$E$11)^($A9)) -> 1830.8784 | F10: =D10-E10 -> 310.57476 | G10: =(1+Inputs!$E$9)^($A10-1)-100% -> 0.18434742 | H10: =D10/(G10+100%) -> 1808.1292 | I10: =E10/(G10+100%) -> 1545.8964 | J10: =J9+F10 -> 1484.6939 | K10: =H10-I10 -> 262.23281 | L10: =L9+K10 -> 1343.9806 | M10: =E10/12 -> 152.5732 | N10: =(E10+800)/12 -> 219.23986 | O10: =D10/12 -> 178.45443 | P10: =D10/E10-1 -> 0.16963156 | Q10: =O10/N10-1 -> -0.18603112
A11: 8 | B11: =IF($A11>Inputs!$E$12,"",Inputs!$E$6*(1+Inputs!$E$8)^($A11-1)) -> 0.50024498 | C11: =IF($A11>Inputs!$E$12,"",Inputs!$E$7*12) -> 4488 | D11: =B11*C11 -> 2245.0995 | E11: =(B11*C11*(1-Inputs!$E$13))+(Inputs!$E$10*12-Inputs!$E$14)*((1+Inputs!$E$11)^($A10)) -> 1895.2461 | F11: =D11-E11 -> 349.85339 | G11: =(1+Inputs!$E$9)^($A11-1)-100% -> 0.21821976 | H11: =D11/(G11+100%) -> 1842.9347 | I11: =E11/(G11+100%) -> 1555.7506 | J11: =J10+F11 -> 1834.5473 | K11: =H11-I11 -> 287.18414 | L11: =L10+K11 -> 1631.1647 | M11: =E11/12 -> 157.93717 | N11: =(E11+800)/12 -> 224.60384 | O11: =D11/12 -> 187.09162 | P11: =D11/E11-1 -> 0.18459523 | Q11: =O11/N11-1 -> -0.16701503
A12: 9 | B12: =IF($A12>Inputs!$E$12,"",Inputs!$E$6*(1+Inputs!$E$8)^($A12-1)) -> 0.52445683 | C12: =IF($A12>Inputs!$E$12,"",Inputs!$E$7*12) -> 4488 | D12: =B12*C12 -> 2353.7623 | E12: =(B12*C12*(1-Inputs!$E$13))+(Inputs!$E$10*12-Inputs!$E$14)*((1+Inputs!$E$11)^($A11)) -> 1961.8805 | F12: =D12-E12 -> 391.88175 | G12: =(1+Inputs!$E$9)^($A12-1)-100% -> 0.25306085 | H12: =D12/(G12+100%) -> 1878.4102 | I12: =E12/(G12+100%) -> 1565.6706 | J12: =J11+F12 -> 2226.429 | K12: =H12-I12 -> 312.7396 | L12: =L11+K12 -> 1943.9043 | M12: =E12/12 -> 163.49004 | N12: =(E12+800)/12 -> 230.15671 | O12: =D12/12 -> 196.14686 | P12: =D12/E12-1 -> 0.19974802 | Q12: =O12/N12-1 -> -0.14776825
A13: 10 | B13: =IF($A13>Inputs!$E$12,"",Inputs!$E$6*(1+Inputs!$E$8)^($A13-1)) -> 0.54984054 | C13: =IF($A13>Inputs!$E$12,"",Inputs!$E$7*12) -> 4488 | D13: =B13*C13 -> 2467.6844 | E13: =(B13*C13*(1-Inputs!$E$13))+(Inputs!$E$10*12-Inputs!$E$14)*((1+Inputs!$E$11)^($A12)) -> 2030.8617 | F13: =D13-E13 -> 436.82262 | G13: =(1+Inputs!$E$9)^($A13-1)-100% -> 0.28889839 | H13: =D13/(G13+100%) -> 1914.5686 | I13: =E13/(G13+100%) -> 1575.657 | J13: =J12+F13 -> 2663.2516 | K13: =H13-I13 -> 338.9116 | L13: =L12+K13 -> 2282.8159 | M13: =E13/12 -> 169.23848 | N13: =(E13+800)/12 -> 235.90515 | O13: =D13/12 -> 205.64036 | P13: =D13/E13-1 -> 0.21509225 | Q13: =O13/N13-1 -> -0.12829216
A14: 11 | B14: =IF($A14>Inputs!$E$12,"",Inputs!$E$6*(1+Inputs!$E$8)^($A14-1)) -> 0.57645283 | C14: =IF($A14>Inputs!$E$12,"",Inputs!$E$7*12) -> 4488 | D14: =B14*C14 -> 2587.1203 | E14: =(B14*C14*(1-Inputs!$E$13))+(Inputs!$E$10*12-Inputs!$E$14)*((1+Inputs!$E$11)^($A13)) -> 2102.2726 | F14: =D14-E14 -> 484.84771 | G14: =(1+Inputs!$E$9)^($A14-1)-100% -> 0.32576088 | H14: =D14/(G14+100%) -> 1951.423 | I14: =E14/(G14+100%) -> 1585.7102 | J14: =J13+F14 -> 3148.0994 | K14: =H14-I14 -> 365.71279 | L14: =L13+K14 -> 2648.5287 | M14: =E14/12 -> 175.18938 | N14: =(E14+800)/12 -> 241.85605 | O14: =D14/12 -> 215.59336 | P14: =D14/E14-1 -> 0.23063028 | Q14: =O14/N14-1 -> -0.10858811
A15: 12 | B15: =IF($A15>Inputs!$E$12,"",Inputs!$E$6*(1+Inputs!$E$8)^($A15-1)) -> 0.60435314 | C15: =IF($A15>Inputs!$E$12,"",Inputs!$E$7*12) -> 4488 | D15: =B15*C15 -> 2712.3369 | E15: =(B15*C15*(1-Inputs!$E$13))+(Inputs!$E$10*12-Inputs!$E$14)*((1+Inputs!$E$11)^($A14)) -> 2176.1988 | F15: =D15-E15 -> 536.13812 | G15: =(1+Inputs!$E$9)^($A15-1)-100% -> 0.36367764 | H15: =D15/(G15+100%) -> 1988.9869 | I15: =E15/(G15+100%) -> 1595.8308 | J15: =J14+F15 -> 3684.2375 | K15: =H15-I15 -> 393.15605 | L15: =L14+K15 -> 3041.6848 | M15: =E15/12 -> 181.3499 | N15: =(E15+800)/12 -> 248.01657 | O15: =D15/12 -> 226.02808 | P15: =D15/E15-1 -> 0.2463645 | Q15: =O15/N15-1 -> -0.088657344
A16: 13 | B16: =IF($A16>Inputs!$E$12,"",Inputs!$E$6*(1+Inputs!$E$8)^($A16-1)) -> 0.63360384 | C16: =IF($A16>Inputs!$E$12,"",Inputs!$E$7*12) -> 4488 | D16: =B16*C16 -> 2843.614 | E16: =(B16*C16*(1-Inputs!$E$13))+(Inputs!$E$10*12-Inputs!$E$14)*((1+Inputs!$E$11)^($A15)) -> 2252.7292 | F16: =D16-E16 -> 590.88481 | G16: =(1+Inputs!$E$9)^($A16-1)-100% -> 0.40267882 | H16: =D16/(G16+100%) -> 2027.2738 | I16: =E16/(G16+100%) -> 1606.0193 | J16: =J15+F16 -> 4275.1223 | K16: =H16-I16 -> 421.25453 | L16: =L15+K16 -> 3462.9393 | M16: =E16/12 -> 187.72743 | N16: =(E16+800)/12 -> 254.3941 | O16: =D16/12 -> 236.96783 | P16: =D16/E16-1 -> 0.26229731 | Q16: =O16/N16-1 -> -0.06850106
... A28: 25 | B28: =IF($A28>Inputs!$E$12,"",Inputs!$E$6*(1+Inputs!$E$8)^($A28-1)) -> 1.1172283 | C28: =IF($A28>Inputs!$E$12,"",Inputs!$E$7*12) -> 4488 | D28: =B28*C28 -> 5014.1208 | E28: =(B28*C28*(1-Inputs!$E$13))+(Inputs!$E$10*12-Inputs!$E$14)*((1+Inputs!$E$11)^($A27)) -> 3411.2007 | F28: =D28-E28 -> 1602.9201 | G28: =(1+Inputs!$E$9)^($A28-1)-100% -> 0.96750788 | H28: =D28/(G28+100%) -> 2548.4629 | I28: =E28/(G28+100%) -> 1733.7673 | J28: =J27+F28 -> 17204.845 | K28: =H28-I28 -> 814.69563 | L28: =L27+K28 -> 10967.285 | M28: =E28/12 -> 284.26673 | N28: =(E28+800)/12 -> 350.9334 | O28: =D28/12 -> 417.8434 | P28: =D28/E28-1 -> 0.46989907 | Q28: =O28/N28-1 -> 0.19066298
B30: TOTALS | D30: =SUM(D4:D28) -> 75291.954 | E30: =SUM(E4:E28) -> 58087.109 | F30: =SUM(F4:F28) -> 17204.845 | H30: =SUM(H4:H28) -> 51162.24 | I30: =SUM(I4:I28) -> 40194.954 | K30: =SUM(K4:K28) -> 10967.285
B32: AVERAGES | D32: =AVERAGE(D4:D28) -> 3011.6782 | E32: =AVERAGE(E4:E28) -> 2323.4843 | F32: =AVERAGE(F4:F28) -> 688.19382 | H32: =AVERAGE(H4:H28) -> 2046.4896 | I32: =AVERAGE(I4:I28) -> 1607.7982 | K32: =AVERAGE(K4:K28) -> 438.69141 | L32: =AVERAGE(L4:L28) -> 4213.6235 | M32: =AVERAGE(M4:M28) -> 193.6237 | N32: =AVERAGE(N4:N28) -> 260.29036
